Workbook

Sheet Özet
C1: MENÜ FİYAT LİSTESİ
B3: Ciao Caffè · Fiyatlar ekran sayfalarına girilir; bu sayfa ve POS listesi formüllerle otomatik güncellenir.
B5: Ekran | C5: Ürün sayısı | D5: Ciao Selection | E5: En düşük fiyat | F5: En yüksek fiyat | G5: Fiyatı eksik
B6: Sıcaklar | C6: =COUNTIF('Tüm Ürünler (POS)'!$B$6:$B$105,B6) -> 44 | D6: =COUNTIFS('Tüm Ürünler (POS)'!$B$6:$B$105,B6,'Tüm Ürünler (POS)'!$J$6:$J$105,"Evet") -> 9 | E6: =_xlfn.MINIFS('Tüm Ürünler (POS)'!$M$6:$M$105,'Tüm Ürünler (POS)'!$B$6:$B$105,B6) -> 70 | F6: =MAX(_xlfn.MAXIFS('Tüm Ürünler (POS)'!$G$6:$G$105,'Tüm Ürünler (POS)'!$B$6:$B$105,B6),_xlfn.MAXIFS('Tüm Ürünler (POS)'!$H$6:$H$105,'Tüm Ürünler (POS)'!$B$6:$B$105,B6),_xlfn.MAXIFS('Tüm Ürünler (POS)'!$I$6:$I$105,'Tüm Ürünler (POS)'!$B$6:$B$105,B6)) -> 340 | G6: =COUNTIFS('Tüm Ürünler (POS)'!$B$6:$B$105,B6,'Tüm Ürünler (POS)'!$L$6:$L$105,"*Fiyat girilecek*") -> 0
B7: Soğuklar | C7: =COUNTIF('Tüm Ürünler (POS)'!$B$6:$B$105,B7) -> 40 | D7: =COUNTIFS('Tüm Ürünler (POS)'!$B$6:$B$105,B7,'Tüm Ürünler (POS)'!$J$6:$J$105,"Evet") -> 8 | E7: =_xlfn.MINIFS('Tüm Ürünler (POS)'!$M$6:$M$105,'Tüm Ürünler (POS)'!$B$6:$B$105,B7) -> 40 | F7: =MAX(_xlfn.MAXIFS('Tüm Ürünler (POS)'!$G$6:$G$105,'Tüm Ürünler (POS)'!$B$6:$B$105,B7),_xlfn.MAXIFS('Tüm Ürünler (POS)'!$H$6:$H$105,'Tüm Ürünler (POS)'!$B$6:$B$105,B7),_xlfn.MAXIFS('Tüm Ürünler (POS)'!$I$6:$I$105,'Tüm Ürünler (POS)'!$B$6:$B$105,B7)) -> 350 | G7: =COUNTIFS('Tüm Ürünler (POS)'!$B$6:$B$105,B7,'Tüm Ürünler (POS)'!$L$6:$L$105,"*Fiyat girilecek*") -> 0
B8: Tatlı & Atıştırmalık | C8: =COUNTIF('Tüm Ürünler (POS)'!$B$6:$B$105,B8) -> 16 | D8: =COUNTIFS('Tüm Ürünler (POS)'!$B$6:$B$105,B8,'Tüm Ürünler (POS)'!$J$6:$J$105,"Evet") -> 3 | E8: =_xlfn.MINIFS('Tüm Ürünler (POS)'!$M$6:$M$105,'Tüm Ürünler (POS)'!$B$6:$B$105,B8) -> 170 | F8: =MAX(_xlfn.MAXIFS('Tüm Ürünler (POS)'!$G$6:$G$105,'Tüm Ürünler (POS)'!$B$6:$B$105,B8),_xlfn.MAXIFS('Tüm Ürünler (POS)'!$H$6:$H$105,'Tüm Ürünler (POS)'!$B$6:$B$105,B8),_xlfn.MAXIFS('Tüm Ürünler (POS)'!$I$6:$I$105,'Tüm Ürünler (POS)'!$B$6:$B$105,B8)) -> 320 | G8: =COUNTIFS('Tüm Ürünler (POS)'!$B$6:$B$105,B8,'Tüm Ürünler (POS)'!$L$6:$L$105,"*Fiyat girilecek*") -> 2
B9: Toplam | C9: =SUM(C6:C8) -> 100 | D9: =SUM(D6:D8) -> 20 | G9: =SUM(G6:G8) -> 2
B11: Boy isimleri
B12: UNICO | C12: Tek ölçü (yalnızca sıcaklarda)
B13: PICCOLO | C13: 12 oz · 350 ml
B14: GRANDE | C14: 16 oz · 470 ml
B16: Renk kodu
B17: Mavi rakam | C17: Elle girilen fiyat (ekran sayfalarında)
B18: Yeşil rakam | C18: Başka sayfadan gelen formül (POS listesi)
B19: Sarı hücre | C19: Girilmesi gereken fiyat

Sheet Sıcaklar
C1: SICAKLAR
B3: UNICO = tek ölçü · PICCOLO = 12 oz / 350 ml · GRANDE = 16 oz / 470 ml · Fiyatlar TL, KDV dahil
B5: ÜRÜN | C5: İÇERİK | D5: UNICO | E5: PICCOLO | F5: GRANDE | G5: ★ | H5: NOT
B7: ESPRESSO BAR
B8: Espresso | C8: Tek shot | D8: 110
B9: Double Espresso | C9: Çift shot | D9: 130
B10: Ristretto | C10: Kısa çekim espresso | D10: 130
B11: Lungo | C11: Uzun çekim espresso | D11: 130
B12: Espresso Macchiato | C12: Espresso · Süt köpüğü | D12: 130
B13: Espresso Con Panna | C13: Espresso · Çırpılmış krema | D13: 150
B14: Cortado | C14: Espresso · Süt | D14: 180
B16: KLASİKLER
B17: Americano | C17: Espresso · Sıcak su | E17: 150 | F17: 170
B18: Long Black | C18: Sıcak su · Espresso | E18: 150 | F18: 170
B19: Caffè Latte | C19: Espresso · Süt | E19: 200 | F19: 220
B20: Cappuccino | C20: Espresso · Bol süt köpüğü | E20: 220 | F20: 240
B21: Flat White | C21: Yoğun espresso · Süt | E21: 210 | F21: 230 | G21: ★
B22: Latte Macchiato | C22: Süt · Espresso | E22: 200 | F22: 220
B23: Filtre Kahve | C23: Taze demlenmiş filtre | E23: 150 | F23: 170
B25: AROMALI KAHVELER
B26: Mocha | C26: Espresso · Çikolata · Süt | E26: 230 | F26: 250
B27: White Mocha | C27: Espresso · Beyaz çikolata · Süt | E27: 230 | F27: 250
B28: Caramel Macchiato | C28: Vanilya · Espresso · Karamel | E28: 230 | F28: 250 | G28: ★
B29: Toffee Nut Latte | C29: Espresso · Karamel · Fındık | E29: 240 | F29: 260
B30: Spanish Latte | C30: Espresso · Yoğunlaştırılmış süt | E30: 250 | F30: 270 | G30: ★
B31: Lotus Latte | C31: Espresso · Vanilya · Biscoff | E31: 270 | F31: 300
B32: Fıstıklı Latte | C32: Espresso · Fıstık kreması · Süt | E32: 300 | F32: 340
B34: KAHVESİZ SICAKLAR
B35: Sıcak Çikolata | C35: Çikolata · Süt | E35: 250 | F35: 270
B36: Beyaz Sıcak Çikolata | C36: Beyaz çikolata · Süt | E36: 250 | F36: 270
B37: Chai Latte | C37: Chai baharatı · Süt | E37: 230 | F37: 250 | G37: ★
B38: Salep | C38: Salep · Süt · Tarçın | E38: 230 | F38: 250
B39: Matcha Latte | C39: Matcha · Süt | E39: 260 | F39: 280
B41: TÜRK KAHVESİ
B42: Türk Kahvesi | C42: Geleneksel, köpüklü | D42: 145
B43: Double Türk Kahvesi | C43: Çift porsiyon | D43: 160
B44: Damla Sakızlı Türk Kahvesi | C44: Damla sakızı | D44: 150 | G44: ★
B45: Double Damla Sakızlı Türk Kahvesi | C45: Çift porsiyon · Damla sakızı | D45: 165
B47: ÇAY & BİTKİ ÇAYLARI
B48: Türk Çayı (Bardak) | D48: 70
...

Sheet Soğuklar
C1: SOĞUKLAR
B3: PICCOLO = 12 oz / 350 ml · GRANDE = 16 oz / 470 ml · Fiyatlar TL, KDV dahil
B5: ÜRÜN | C5: İÇERİK | D5: PICCOLO | E5: GRANDE | F5: ★ | G5: NOT
B7: BUZLU KAHVELER
B8: Iced Americano | C8: Espresso · Soğuk su · Buz | D8: 170 | E8: 190
B9: Iced Latte | C9: Espresso · Süt · Buz | D9: 220 | E9: 240
B10: Iced Cappuccino | C10: Espresso · Süt · Soğuk köpük | D10: 240 | E10: 260
B11: Iced Flat White | C11: Yoğun espresso · Süt · Buz | D11: 230 | E11: 250
B12: Iced Espresso Tonic | C12: Espresso · Tonik · Buz | D12: 250 | E12: 280 | F12: ★
B13: Iced Coffee Frappé | C13: Granül kahve · Buz · Süt | D13: 150 | E13: 170
B14: Iced Cappuccino Affogato | C14: Espresso · Süt · Dondurma | D14: 250 | E14: 270
B16: COLD BREW & SOĞUK FİLTRE
B17: Iced Filter Coffee | C17: Soğutulmuş filtre · Buz | D17: 150 | E17: 170
B18: Iced Filter Coffee Milky | C18: Soğutulmuş filtre · Süt · Buz | D18: 170 | E18: 190
B20: ICED TEA
B21: Iced Tea | C21: Mango · Nar · Limon · Yaban mersini | D21: 170 | E21: 190 | F21: ★
B23: AROMALI BUZLULAR
B24: Iced Mocha | C24: Espresso · Çikolata · Süt | D24: 250 | E24: 270
B25: Iced White Mocha | C25: Espresso · Beyaz çikolata | D25: 250 | E25: 270
B26: Iced Caramel Macchiato | C26: Vanilya · Karamel | D26: 250 | E26: 270
B27: Iced Dirty Chai Latte | C27: Chai latte · Espresso | D27: 240 | E27: 260
B28: Iced Spanish Latte | C28: Espresso · Kondanse süt | D28: 260 | E28: 280 | F28: ★
B29: Iced Pistachio Latte | C29: Espresso · Fıstık · Süt | D29: 300 | E29: 340
B31: SHAKE & SMOOTHIE
B32: Milkshake | C32: Çikolata · Vanilya · Çilek · Antep fıstıklı | D32: 280 | E32: 300 | F32: ★
B33: Frozen | C33: Meyve püresi · Soda · Buz | D33: 270 | E33: 290
B34: Smoothie | C34: Süzme yoğurt · Meyve | D34: 270 | E34: 290
B35: Pistachio Banana Protein | C35: Fıstık · Muz · Yulaf | D35: 300 | E35: 320
B36: Orman Meyveli Protein | C36: Badem sütü · Yoğurt · Yulaf | D36: 300 | E36: 320
B38: KAHVESİZ BUZLULAR
B39: Iced Chocolatte | C39: Çikolata · Süt · Buz | D39: 260 | E39: 280
B40: Iced White Chocolatte | C40: Beyaz çikolata · Süt | D40: 260 | E40: 280
B41: Iced Chai Latte | C41: Chai · Süt · Buz | D41: 240 | E41: 260
B42: Iced Matcha | C42: Matcha · Süt · Buz | D42: 270 | E42: 290 | F42: ★
B44: BOBA & FIZZ
B45: Taro Milk Boba Tea | C45: Taro · Süt · Boba | D45: 300 | E45: 320 | F45: ★
B46: Matcha Milk Boba Tea | C46: Matcha · Süt · Boba | D46: 330 | E46: 350
B47: Ocean Blue Fizz | C47: Blue curaçao · Soda · Boba | D47: 290 | E47: 310
B48: Berry Burst | C48: Ahududu · Soda · Çilek boba | D48: 290 | E48: 310
B49: Green Apple Fizz | C49: Yeşil elma · Gazoz · Boba | D49: 290 | E49: 310
...

Sheet Tatlı & Atıştırmalık
C1: TATLI & ATIŞTIRMALIK
B3: Menü adı ekranda büyük, asıl ürün adı altında küçük yazar · Fiyatlar TL, KDV dahil
B5: MENÜ ADI | C5: ASIL ÜRÜN | D5: İÇERİK | E5: FİYAT | F5: ★ | G5: NOT
B7: PASTA & KEK
B8: Monet'nin Bahçesi | C8: Havuçlu Kek | D8: Havuç · Tarçın · Ceviz · Krem peynirli krema | E8: 250
B9: Moulin Rouge | C9: Cheesecake | D9: Bisküvi taban · Kırmızı meyve sosu | E9: 270
B10: Frida | C10: Berry Hibiscus | D10: Orman meyveleri · Hibiskus · Krema | E10: 270
B11: Mavi Dönem | C11: Yaban Mersinli Pasta | D11: Pandispanya · Krema · Yaban mersini | E11: 300
B12: Altın Lotus | C12: Lotus Biscoff Kek | D12: Karamelize krema · Lotus bisküvi | E12: 320 | F12: ★
B13: Çikolata Fabrikası | C13: Nutella Cookie Kek | D13: Cookie hamuru · Nutella | E13: 250
B14: Copacabana | C14: Cocostar Pasta | D14: Kakaolu kek · Hindistan cevizli krema | E14: 240
B15: Gaudí | C15: Mozaik Kek | D15: Bisküvi · Kakao · Çikolata | E15: 200 | F15: ★
B17: TATLILAR
B18: Noir | C18: Brownie | D18: Yoğun bitter çikolata · Islak doku | E18: 300 | F18: ★
B19: Kuğu Gölü | C19: Profiterol | D19: Choux · Vanilyalı krema · Çikolata sos | E19: 300
B20: Chocolat | C20: Çikolatalı Cookie | D20: Bitter ve sütlü çikolata parçaları | E20: 200
B21: Roma Tatili | C21: Dondurma | D21: Cup · 4 top | E21: 170
B23: SANDVİÇLER
B24: Vegan Sandviç | D24: Hayvansal ürün içermez · Taze sebzeler | E24: 200
B25: Karışık Sandviç | D25: Dana jambon · Kaşar · Süzme peynir · Domates · Yeşillik | E25: 250
B27: PİZZA
B28: Pulp Fetta | C28: Dilim Pizza | D28: Tek dilim · Günün çeşidi | G28: Yakında · Fiyat girilecek
B29: Il Padrino | C29: Tam Pizza | D29: Bütün pizza · Paylaşmalık | G29: Yakında · Fiyat girilecek
B31: ★ Ciao Selection = baristanın seçtiği ürünler · Mavi rakamlar düzenlenebilir fiyatlardır, sarı hücreler girilmesi gereken fiyatlardır.

Sheet Tüm Ürünler (POS)
C1: TÜM ÜRÜNLER · POS
B3: Kasa (Simpra) için düz liste · fiyatlar ekran sayfalarından formülle gelir (yeşil)
B5: Ekran | C5: Kategori | D5: Menü Adı | E5: Asıl Ürün Adı | F5: İçerik | G5: UNICO / Tek Fiyat | H5: PICCOLO 12 oz | I5: GRANDE 16 oz | J5: Ciao Selection | K5: Signature | L5: Not | M5: Başlangıç Fiyatı
B6: Sıcaklar | C6: ESPRESSO BAR | D6: Espresso | F6: Tek shot | G6: =IF(Sıcaklar!D8="","",Sıcaklar!D8) -> 110 | H6: =IF(Sıcaklar!E8="","",Sıcaklar!E8) | I6: =IF(Sıcaklar!F8="","",Sıcaklar!F8) | M6: =IF(COUNT(G6:I6)=0,"",MIN(G6:I6)) -> 110
B7: Sıcaklar | C7: ESPRESSO BAR | D7: Double Espresso | F7: Çift shot | G7: =IF(Sıcaklar!D9="","",Sıcaklar!D9) -> 130 | H7: =IF(Sıcaklar!E9="","",Sıcaklar!E9) | I7: =IF(Sıcaklar!F9="","",Sıcaklar!F9) | M7: =IF(COUNT(G7:I7)=0,"",MIN(G7:I7)) -> 130
B8: Sıcaklar | C8: ESPRESSO BAR | D8: Ristretto | F8: Kısa çekim espresso | G8: =IF(Sıcaklar!D10="","",Sıcaklar!D10) -> 130 | H8: =IF(Sıcaklar!E10="","",Sıcaklar!E10) | I8: =IF(Sıcaklar!F10="","",Sıcaklar!F10) | M8: =IF(COUNT(G8:I8)=0,"",MIN(G8:I8)) -> 130
B9: Sıcaklar | C9: ESPRESSO BAR | D9: Lungo | F9: Uzun çekim espresso | G9: =IF(Sıcaklar!D11="","",Sıcaklar!D11) -> 130 | H9: =IF(Sıcaklar!E11="","",Sıcaklar!E11) | I9: =IF(Sıcaklar!F11="","",Sıcaklar!F11) | M9: =IF(COUNT(G9:I9)=0,"",MIN(G9:I9)) -> 130
B10: Sıcaklar | C10: ESPRESSO BAR | D10: Espresso Macchiato | F10: Espresso · Süt köpüğü | G10: =IF(Sıcaklar!D12="","",Sıcaklar!D12) -> 130 | H10: =IF(Sıcaklar!E12="","",Sıcaklar!E12) | I10: =IF(Sıcaklar!F12="","",Sıcaklar!F12) | M10: =IF(COUNT(G10:I10)=0,"",MIN(G10:I10)) -> 130
B11: Sıcaklar | C11: ESPRESSO BAR | D11: Espresso Con Panna | F11: Espresso · Çırpılmış krema | G11: =IF(Sıcaklar!D13="","",Sıcaklar!D13) -> 150 | H11: =IF(Sıcaklar!E13="","",Sıcaklar!E13) | I11: =IF(Sıcaklar!F13="","",Sıcaklar!F13) | M11: =IF(COUNT(G11:I11)=0,"",MIN(G11:I11)) -> 150
B12: Sıcaklar | C12: ESPRESSO BAR | D12: Cortado | F12: Espresso · Süt | G12: =IF(Sıcaklar!D14="","",Sıcaklar!D14) -> 180 | H12: =IF(Sıcaklar!E14="","",Sıcaklar!E14) | I12: =IF(Sıcaklar!F14="","",Sıcaklar!F14) | M12: =IF(COUNT(G12:I12)=0,"",MIN(G12:I12)) -> 180
B13: Sıcaklar | C13: KLASİKLER | D13: Americano | F13: Espresso · Sıcak su | G13: =IF(Sıcaklar!D17="","",Sıcaklar!D17) | H13: =IF(Sıcaklar!E17="","",Sıcaklar!E17) -> 150 | I13: =IF(Sıcaklar!F17="","",Sıcaklar!F17) -> 170 | M13: =IF(COUNT(G13:I13)=0,"",MIN(G13:I13)) -> 150
B14: Sıcaklar | C14: KLASİKLER | D14: Long Black | F14: Sıcak su · Espresso | G14: =IF(Sıcaklar!D18="","",Sıcaklar!D18) | H14: =IF(Sıcaklar!E18="","",Sıcaklar!E18) -> 150 | I14: =IF(Sıcaklar!F18="","",Sıcaklar!F18) -> 170 | M14: =IF(COUNT(G14:I14)=0,"",MIN(G14:I14)) -> 150
B15: Sıcaklar | C15: KLASİKLER | D15: Caffè Latte | F15: Espresso · Süt | G15: =IF(Sıcaklar!D19="","",Sıcaklar!D19) | H15: =IF(Sıcaklar!E19="","",Sıcaklar!E19) -> 200 | I15: =IF(Sıcaklar!F19="","",Sıcaklar!F19) -> 220 | M15: =IF(COUNT(G15:I15)=0,"",MIN(G15:I15)) -> 200
B16: Sıcaklar | C16: KLASİKLER | D16: Cappuccino | F16: Espresso · Bol süt köpüğü | G16: =IF(Sıcaklar!D20="","",Sıcaklar!D20) | H16: =IF(Sıcaklar!E20="","",Sıcaklar!E20) -> 220 | I16: =IF(Sıcaklar!F20="","",Sıcaklar!F20) -> 240 | M16: =IF(COUNT(G16:I16)=0,"",MIN(G16:I16)) -> 220
B17: Sıcaklar | C17: KLASİKLER | D17: Flat White | F17: Yoğun espresso · Süt | G17: =IF(Sıcaklar!D21="","",Sıcaklar!D21) | H17: =IF(Sıcaklar!E21="","",Sıcaklar!E21) -> 210 | I17: =IF(Sıcaklar!F21="","",Sıcaklar!F21) -> 230 | J17: Evet | M17: =IF(COUNT(G17:I17)=0,"",MIN(G17:I17)) -> 210
B18: Sıcaklar | C18: KLASİKLER | D18: Latte Macchiato | F18: Süt · Espresso | G18: =IF(Sıcaklar!D22="","",Sıcaklar!D22) | H18: =IF(Sıcaklar!E22="","",Sıcaklar!E22) -> 200 | I18: =IF(Sıcaklar!F22="","",Sıcaklar!F22) -> 220 | M18: =IF(COUNT(G18:I18)=0,"",MIN(G18:I18)) -> 200
B19: Sıcaklar | C19: KLASİKLER | D19: Filtre Kahve | F19: Taze demlenmiş filtre | G19: =IF(Sıcaklar!D23="","",Sıcaklar!D23) | H19: =IF(Sıcaklar!E23="","",Sıcaklar!E23) -> 150 | I19: =IF(Sıcaklar!F23="","",Sıcaklar!F23) -> 170 | M19: =IF(COUNT(G19:I19)=0,"",MIN(G19:I19)) -> 150
B20: Sıcaklar | C20: AROMALI KAHVELER | D20: Mocha | F20: Espresso · Çikolata · Süt | G20: =IF(Sıcaklar!D26="","",Sıcaklar!D26) | H20: =IF(Sıcaklar!E26="","",Sıcaklar!E26) -> 230 | I20: =IF(Sıcaklar!F26="","",Sıcaklar!F26) -> 250 | M20: =IF(COUNT(G20:I20)=0,"",MIN(G20:I20)) -> 230
B21: Sıcaklar | C21: AROMALI KAHVELER | D21: White Mocha | F21: Espresso · Beyaz çikolata · Süt | G21: =IF(Sıcaklar!D27="","",Sıcaklar!D27) | H21: =IF(Sıcaklar!E27="","",Sıcaklar!E27) -> 230 | I21: =IF(Sıcaklar!F27="","",Sıcaklar!F27) -> 250 | M21: =IF(COUNT(G21:I21)=0,"",MIN(G21:I21)) -> 230
B22: Sıcaklar | C22: AROMALI KAHVELER | D22: Caramel Macchiato | F22: Vanilya · Espresso · Karamel | G22: =IF(Sıcaklar!D28="","",Sıcaklar!D28) | H22: =IF(Sıcaklar!E28="","",Sıcaklar!E28) -> 230 | I22: =IF(Sıcaklar!F28="","",Sıcaklar!F28) -> 250 | J22: Evet | M22: =IF(COUNT(G22:I22)=0,"",MIN(G22:I22)) -> 230
B23: Sıcaklar | C23: AROMALI KAHVELER | D23: Toffee Nut Latte | F23: Espresso · Karamel · Fındık | G23: =IF(Sıcaklar!D29="","",Sıcaklar!D29) | H23: =IF(Sıcaklar!E29="","",Sıcaklar!E29) -> 240 | I23: =IF(Sıcaklar!F29="","",Sıcaklar!F29) -> 260 | M23: =IF(COUNT(G23:I23)=0,"",MIN(G23:I23)) -> 240
B24: Sıcaklar | C24: AROMALI KAHVELER | D24: Spanish Latte | F24: Espresso · Yoğunlaştırılmış süt | G24: =IF(Sıcaklar!D30="","",Sıcaklar!D30) | H24: =IF(Sıcaklar!E30="","",Sıcaklar!E30) -> 250 | I24: =IF(Sıcaklar!F30="","",Sıcaklar!F30) -> 270 | J24: Evet | M24: =IF(COUNT(G24:I24)=0,"",MIN(G24:I24)) -> 250
B25: Sıcaklar | C25: AROMALI KAHVELER | D25: Lotus Latte | F25: Espresso · Vanilya · Biscoff | G25: =IF(Sıcaklar!D31="","",Sıcaklar!D31) | H25: =IF(Sıcaklar!E31="","",Sıcaklar!E31) -> 270 | I25: =IF(Sıcaklar!F31="","",Sıcaklar!F31) -> 300 | M25: =IF(COUNT(G25:I25)=0,"",MIN(G25:I25)) -> 270
B26: Sıcaklar | C26: AROMALI KAHVELER | D26: Fıstıklı Latte | F26: Espresso · Fıstık kreması · Süt | G26: =IF(Sıcaklar!D32="","",Sıcaklar!D32) | H26: =IF(Sıcaklar!E32="","",Sıcaklar!E32) -> 300 | I26: =IF(Sıcaklar!F32="","",Sıcaklar!F32) -> 340 | M26: =IF(COUNT(G26:I26)=0,"",MIN(G26:I26)) -> 300
B27: Sıcaklar | C27: KAHVESİZ SICAKLAR | D27: Sıcak Çikolata | F27: Çikolata · Süt | G27: =IF(Sıcaklar!D35="","",Sıcaklar!D35) | H27: =IF(Sıcaklar!E35="","",Sıcaklar!E35) -> 250 | I27: =IF(Sıcaklar!F35="","",Sıcaklar!F35) -> 270 | M27: =IF(COUNT(G27:I27)=0,"",MIN(G27:I27)) -> 250
B28: Sıcaklar | C28: KAHVESİZ SICAKLAR | D28: Beyaz Sıcak Çikolata | F28: Beyaz çikolata · Süt | G28: =IF(Sıcaklar!D36="","",Sıcaklar!D36) | H28: =IF(Sıcaklar!E36="","",Sıcaklar!E36) -> 250 | I28: =IF(Sıcaklar!F36="","",Sıcaklar!F36) -> 270 | M28: =IF(COUNT(G28:I28)=0,"",MIN(G28:I28)) -> 250
B29: Sıcaklar | C29: KAHVESİZ SICAKLAR | D29: Chai Latte | F29: Chai baharatı · Süt | G29: =IF(Sıcaklar!D37="","",Sıcaklar!D37) | H29: =IF(Sıcaklar!E37="","",Sıcaklar!E37) -> 230 | I29: =IF(Sıcaklar!F37="","",Sıcaklar!F37) -> 250 | J29: Evet | M29: =IF(COUNT(G29:I29)=0,"",MIN(G29:I29)) -> 230
B30: Sıcaklar | C30: KAHVESİZ SICAKLAR | D30: Salep | F30: Salep · Süt · Tarçın | G30: =IF(Sıcaklar!D38="","",Sıcaklar!D38) | H30: =IF(Sıcaklar!E38="","",Sıcaklar!E38) -> 230 | I30: =IF(Sıcaklar!F38="","",Sıcaklar!F38) -> 250 | M30: =IF(COUNT(G30:I30)=0,"",MIN(G30:I30)) -> 230
B31: Sıcaklar | C31: KAHVESİZ SICAKLAR | D31: Matcha Latte | F31: Matcha · Süt | G31: =IF(Sıcaklar!D39="","",Sıcaklar!D39) | H31: =IF(Sıcaklar!E39="","",Sıcaklar!E39) -> 260 | I31: =IF(Sıcaklar!F39="","",Sıcaklar!F39) -> 280 | M31: =IF(COUNT(G31:I31)=0,"",MIN(G31:I31)) -> 260
B32: Sıcaklar | C32: TÜRK KAHVESİ | D32: Türk Kahvesi | F32: Geleneksel, köpüklü | G32: =IF(Sıcaklar!D42="","",Sıcaklar!D42) -> 145 | H32: =IF(Sıcaklar!E42="","",Sıcaklar!E42) | I32: =IF(Sıcaklar!F42="","",Sıcaklar!F42) | M32: =IF(COUNT(G32:I32)=0,"",MIN(G32:I32)) -> 145
B33: Sıcaklar | C33: TÜRK KAHVESİ | D33: Double Türk Kahvesi | F33: Çift porsiyon | G33: =IF(Sıcaklar!D43="","",Sıcaklar!D43) -> 160 | H33: =IF(Sıcaklar!E43="","",Sıcaklar!E43) | I33: =IF(Sıcaklar!F43="","",Sıcaklar!F43) | M33: =IF(COUNT(G33:I33)=0,"",MIN(G33:I33)) -> 160
B34: Sıcaklar | C34: TÜRK KAHVESİ | D34: Damla Sakızlı Türk Kahvesi | F34: Damla sakızı | G34: =IF(Sıcaklar!D44="","",Sıcaklar!D44) -> 150 | H34: =IF(Sıcaklar!E44="","",Sıcaklar!E44) | I34: =IF(Sıcaklar!F44="","",Sıcaklar!F44) | J34: Evet | M34: =IF(COUNT(G34:I34)=0,"",MIN(G34:I34)) -> 150
B35: Sıcaklar | C35: TÜRK KAHVESİ | D35: Double Damla Sakızlı Türk Kahvesi | F35: Çift porsiyon · Damla sakızı | G35: =IF(Sıcaklar!D45="","",Sıcaklar!D45) -> 165 | H35: =IF(Sıcaklar!E45="","",Sıcaklar!E45) | I35: =IF(Sıcaklar!F45="","",Sıcaklar!F45) | M35: =IF(COUNT(G35:I35)=0,"",MIN(G35:I35)) -> 165
B36: Sıcaklar | C36: ÇAY & BİTKİ ÇAYLARI | D36: Türk Çayı (Bardak) | G36: =IF(Sıcaklar!D48="","",Sıcaklar!D48) -> 70 | H36: =IF(Sıcaklar!E48="","",Sıcaklar!E48) | I36: =IF(Sıcaklar!F48="","",Sıcaklar!F48) | M36: =IF(COUNT(G36:I36)=0,"",MIN(G36:I36)) -> 70
B37: Sıcaklar | C37: ÇAY & BİTKİ ÇAYLARI | D37: Türk Çayı (Fincan) | G37: =IF(Sıcaklar!D49="","",Sıcaklar!D49) -> 90 | H37: =IF(Sıcaklar!E49="","",Sıcaklar!E49) | I37: =IF(Sıcaklar!F49="","",Sıcaklar!F49) | M37: =IF(COUNT(G37:I37)=0,"",MIN(G37:I37)) -> 90
B38: Sıcaklar | C38: ÇAY & BİTKİ ÇAYLARI | D38: Türk Çayı (Karton) | F38: Karton bardak | G38: =IF(Sıcaklar!D50="","",Sıcaklar!D50) | H38: =IF(Sıcaklar!E50="","",Sıcaklar!E50) -> 100 | I38: =IF(Sıcaklar!F50="","",Sıcaklar!F50) -> 110 | L38: Ekranda gösterilmez (POS) | M38: =IF(COUNT(G38:I38)=0,"",MIN(G38:I38)) -> 100
B39: Sıcaklar | C39: ÇAY & BİTKİ ÇAYLARI | D39: Yeşil Çay | F39: Hafif yeşil çay | G39: =IF(Sıcaklar!D51="","",Sıcaklar!D51) -> 130 | H39: =IF(Sıcaklar!E51="","",Sıcaklar!E51) | I39: =IF(Sıcaklar!F51="","",Sıcaklar!F51) | M39: =IF(COUNT(G39:I39)=0,"",MIN(G39:I39)) -> 130
B40: Sıcaklar | C40: ÇAY & BİTKİ ÇAYLARI | D40: Papatya | F40: Kuru papatya | G40: =IF(Sıcaklar!D52="","",Sıcaklar!D52) -> 130 | H40: =IF(Sıcaklar!E52="","",Sıcaklar!E52) | I40: =IF(Sıcaklar!F52="","",Sıcaklar!F52) | M40: =IF(COUNT(G40:I40)=0,"",MIN(G40:I40)) -> 130
B41: Sıcaklar | C41: ÇAY & BİTKİ ÇAYLARI | D41: Ihlamur | F41: Ihlamur çiçeği | G41: =IF(Sıcaklar!D53="","",Sıcaklar!D53) -> 130 | H41: =IF(Sıcaklar!E53="","",Sıcaklar!E53) | I41: =IF(Sıcaklar!F53="","",Sıcaklar!F53) | M41: =IF(COUNT(G41:I41)=0,"",MIN(G41:I41)) -> 130
B42: Sıcaklar | C42: ÇAY & BİTKİ ÇAYLARI | D42: Nane Limon | F42: Nane · Limon | G42: =IF(Sıcaklar!D54="","",Sıcaklar!D54) -> 130 | H42: =IF(Sıcaklar!E54="","",Sıcaklar!E54) | I42: =IF(Sıcaklar!F54="","",Sıcaklar!F54) | M42: =IF(COUNT(G42:I42)=0,"",MIN(G42:I42)) -> 130
...
